Workbook

Sheet Production
A1: Facility | B1: Production Size (gallons) | C1: Type | D1: Source
A2: Twelve's Moses Lake facility | B2: 50000 | C2: E-Jet SAF | D2: https://trellis.net/article/alaska-airlines-microsoft-twelve-sustainable-aviation-fuel/

Sheet Targets
A1: Country | B1: Year | C1: Type | D1: Size (Blend) | E1: Size (Gallons) | F1: Actual
A2: UK | B2: 2025 | C2: Blend | D2: 0.02 | E2: na
A3: UK | B3: 2030 | C3: Blend | D3: 0.1 | E3: na
A4: UK | B4: 2040 | C4: Blend | D4: 0.22 | E4: na
A5: UK | B5: 2050 | C5: Blend | D5: Net Zero | E5: na
A6: EU | B6: 2025 | C6: Blend | D6: 0.02 | E6: na
A7: EU | B7: 2030 | C7: Blend | D7: 0.06 | E7: na
A8: EU | B8: 2040 | C8: Blend | D8: 0.34 | E8: na
A9: EU | B9: 2050 | C9: Blend | D9: 0.7 | E9: na
A10: US | B10: 2030 | C10: Production | D10: na | E10: 3
A11: US | B11: 2050 | C11: Production | D11: na | E11: 35
A12: US | B12: 2024 | C12: Production | D12: na | E12: 0.039
A13: US | B13: 2030 | C13: Optimistic Production | E13: 2.1

Sheet Alaska Report
A1: Year | B1: ASMs | C1: RPMs | D1: Passengers | E1: Fuel gallons | F1: ASMs/gal | G1: Economic fuel $/gal | H1: RASM | I1: PRASM | J1: CASMex | K1: Operating Revenue | L1: Fuel expense | M1: Adjusted Pretax margin
A2: 2024 PF | B2: 91208000000 | C2: 76566000000 | D2: 57134000 | E2: 1123000000 | F2: 81.2 | G2: 2.74 | H2: 0.1511 | I2: 0.1371 | J2: 0.1091 | K2: 13779000000 | L2: 3075000000 | M2: 0.071
A3: 2025 | B3: 92962000000 | C3: 77110000000 | D3: 58627000 | E3: 1146000000 | F3: 81.1 | G3: 2.52 | H3: 0.1532 | I3: 0.1381 | J3: 0.1142 | K3: 14239000000 | L3: 2883000000 | M3: 0.028
A5: YoY Growth | B5: =(B3-B2)/B2 -> 0.019230769 | C5: =(C3-C2)/C2 -> 0.0071049813 | D5: =(D3-D2)/D2 -> 0.02613155 | E5: =(E3-E2)/E2 -> 0.020480855 | F5: =(F3-F2)/F2 -> -0.0012315271 | G5: =(G3-G2)/G2 -> -0.080291971 | H5: =(H3-H2)/H2 -> 0.013898081 | I5: =(I3-I2)/I2 -> 0.007293946 | ... M5: =(M3-M2)/M2 -> -0.6056338

Sheet Alaska Base
A1: Metric | B1: Year | C1: Value | D1: Units | E1: Source
A2: 2019 GHG Intensity Baseline | B2: 2019 | C2: 1.39 | D2: metric tons CO₂e / 1,000 RTM | E2: Sustain Report | G2: Derived metric | H2: Value
A3: 2025 GHG Intensity | B3: 2025 | C3: 1.33 | D3: metric tons CO2e / 1,000 RTM | E3: 2025 Impact Report | G3: Environmental_Total_Fuel | H3: =C4+C5 -> 1090676144
A4: 2025 Conventional Jet Fuel | B4: 2025 | C4: 1079785000 | D4: gallons | E4: 2025 Impact Report | G4: Environmental_SAF_Share | H4: =C20 -> 0.009985681
A5: 2025 SAF | B5: 2025 | C5: 10891144 | D5: gallons | E5: 2025 Impact Report | G5: Operating_SAF_Share | H5: =C19 -> 0.0095036161
A6: 2025 Operating Aircraft Fuel | B6: 2025 | C6: 1146000000 | D6: gallons | E6: 2025 10-K / operating statistics | G6: Observed_ASM_Growth | H6: =C11/C10-1 -> 0.019230769
A7: 2025 Into-plane Fuel Price | B7: 2025 | C7: 2.51 | D7: $/gallon | E7: 2025 10-K
A8: 2025 Total Operating Revenue | B8: 2025 | C8: 14239000000 | D8: $ | E8: 2025 10-K
A9: 2025 Passenger Revenue | B9: 2025 | C9: 12835000000 | D9: $ | E9: 2025 10-K
A10: 2024 PF ASM | B10: 2024 | C10: 91208000000 | D10: ASM | E10: 2025 10-K pro forma
A11: 2025 ASM | B11: 2025 | C11: 92962000000 | D11: ASM | E11: 2025 10-K
A12: 2025 Aircraft Scope 1 emissions | B12: 2025 | C12: 10428326 | D12: tCO2e | E12: 2025 Impact Report
A13: 2025 Vehicle Scope 1 emissions | B13: 2025 | C13: 13789 | D13: tCO2e | E13: 2025 Impact Report
A14: 2025 Facility heating Scope 1 emissions | B14: 2025 | C14: 6385 | D14: tCO2e | E14: 2025 Impact Report
A15: 2025 SAF N2O Scope 1 emissions | B15: 2025 | C15: 866 | D15: tCO2e | E15: 2025 Impact Report
A16: 2025 Scope 2 market-based emissions | B16: 2025 | C16: 13321 | D16: tCO2e | E16: 2025 Impact Report
A17: 2025 Scope 1 total | B17: 2025 | C17: 10449366 | D17: tCO2e | E17: 2025 Impact Report
A18: 2025 implied RTM | B18: 2025 | C18: =C12/C3*1000 -> 7.8408466e+09 | D18: RTM | E18: Derived: aircraft Scope 1 / GHG intensity × 1,000
A19: 2025 operating SAF share | B19: 2025 | C19: =C5/C6 -> 0.0095036161 | D19: % of operating fuel | E19: Derived: SAF gallons / operating aircraft fuel
A20: 2025 environmental-reporting SAF share | B20: 2025 | C20: =C5/(C4+C5) -> 0.009985681 | D20: % of env. fuel | E20: Derived: SAF / (conventional + SAF)
A21: 2025 Scope 3 total (context only) | B21: 2025 | C21: 3829342 | D21: tCO2e | E21: 2025 Impact Report; excluded from v1 operational net-zero model
A22: 2025 Cash & Cash Equivalents | B22: 2025 | C22: 627000000 | D22: $ | E22: 2025 10-K
A23: 2025 Marketable Securities | B23: 2025 | C23: 1496000000 | D23: $ | E23: 2025 10-K
A24: 2025 Cash + Marketable Securities | B24: 2025 | C24: =C22+C23 -> 2123000000 | D24: $ | E24: Derived
A25: 2025 Available Liquidity | B25: 2025 | C25: 2973000000 | D25: $ | E25: 2025 10-K; includes unused line of credit
A26: 2025 Operating Cash Flow | B26: 2025 | C26: 1200000000 | D26: $ | E26: 2025 10-K
A27: 2025 Capital Expenditures | B27: 2025 | C27: 1600000000 | D27: $ | E27: 2025 10-K
A28: 2026 Planned Capital Expenditures — midpoint | B28: 2026 | C28: 1450000000 | D28: $ | E28: 2026 Q1 10-Q guidance $1.4B–$1.5B
A29: 2031–2035 Aggregate Aircraft Commitments | B29: 2031 | C29: 4264000000 | D29: $ | E29: 2026 Q2 10-Q; 'thereafter' after 2030

Sheet EIA_AEO
A1: Year | B1: Fuel Cost (1987 dollars per MMBtu) | C1: Fuel Price Index: | D1: Aircraft Efficiency: Average Aircraft | E1: Efficiency Index | F1: Commercial Jet Fuel (US): Fuel Consumption (trillion Btu)
A2: 2025 | B2: 6.6966219 | C2: =B2/ _xlfn.XLOOKUP(2025,$A$2:$A$27,$B$2:$B$27) -> 1 | D2: 85.781158 | E2: =D2/ _xlfn.XLOOKUP(2025,$A$2:$A$27,$D$2:$D$27) -> 1 | F2: 3230.0942
A3: 2026 | B3: 5.9723396 | C3: =B3/ _xlfn.XLOOKUP(2025,$A$2:$A$27,$B$2:$B$27) -> 0.89184364 | D3: 86.455696 | E3: =D3/ _xlfn.XLOOKUP(2025,$A$2:$A$27,$D$2:$D$27) -> 1.0078635 | F3: 3275.9133
A4: 2027 | B4: 6.4054852 | C4: =B4/ _xlfn.XLOOKUP(2025,$A$2:$A$27,$B$2:$B$27) -> 0.95652484 | D4: 87.136665 | E4: =D4/ _xlfn.XLOOKUP(2025,$A$2:$A$27,$D$2:$D$27) -> 1.0158019 | F4: 3303.1797
A5: 2028 | B5: 6.5878377 | C5: =B5/ _xlfn.XLOOKUP(2025,$A$2:$A$27,$B$2:$B$27) -> 0.98375536 | D5: 87.83371 | E5: =D5/ _xlfn.XLOOKUP(2025,$A$2:$A$27,$D$2:$D$27) -> 1.0239278 | F5: 3304.9766
A6: 2029 | B6: 6.7469621 | C6: =B6/ _xlfn.XLOOKUP(2025,$A$2:$A$27,$B$2:$B$27) -> 1.0075172 | D6: 88.507492 | E6: =D6/ _xlfn.XLOOKUP(2025,$A$2:$A$27,$D$2:$D$27) -> 1.0317824 | F6: 3320.0674
A7: 2030 | B7: 6.7818222 | C7: =B7/ _xlfn.XLOOKUP(2025,$A$2:$A$27,$B$2:$B$27) -> 1.0127229 | D7: 89.191437 | E7: =D7/ _xlfn.XLOOKUP(2025,$A$2:$A$27,$D$2:$D$27) -> 1.0397556 | F7: 3347.7463
A8: 2031 | B8: 6.7284436 | C8: =B8/ _xlfn.XLOOKUP(2025,$A$2:$A$27,$B$2:$B$27) -> 1.0047519 | D8: 89.892052 | E8: =D8/ _xlfn.XLOOKUP(2025,$A$2:$A$27,$D$2:$D$27) -> 1.047923 | F8: 3372.7368
A9: 2032 | B9: 6.7404766 | C9: =B9/ _xlfn.XLOOKUP(2025,$A$2:$A$27,$B$2:$B$27) -> 1.0065488 | D9: 90.644325 | E9: =D9/ _xlfn.XLOOKUP(2025,$A$2:$A$27,$D$2:$D$27) -> 1.0566927 | F9: 3400.6318
A10: 2033 | B10: 6.9223495 | C10: =B10/ _xlfn.XLOOKUP(2025,$A$2:$A$27,$B$2:$B$27) -> 1.0337077 | D10: 91.404976 | E10: =D10/ _xlfn.XLOOKUP(2025,$A$2:$A$27,$D$2:$D$27) -> 1.0655601 | F10: 3436.5942
A11: 2034 | B11: 7.1716175 | C11: =B11/ _xlfn.XLOOKUP(2025,$A$2:$A$27,$B$2:$B$27) -> 1.0709306 | D11: 92.163483 | E11: =D11/ _xlfn.XLOOKUP(2025,$A$2:$A$27,$D$2:$D$27) -> 1.0744024 | F11: 3481.7234
A12: 2035 | B12: 7.2526112 | C12: =B12/ _xlfn.XLOOKUP(2025,$A$2:$A$27,$B$2:$B$27) -> 1.0830253 | D12: 92.923798 | E12: =D12/ _xlfn.XLOOKUP(2025,$A$2:$A$27,$D$2:$D$27) -> 1.0832658 | F12: 3531.4907
A13: 2036 | B13: 7.3257723 | C13: =B13/ _xlfn.XLOOKUP(2025,$A$2:$A$27,$B$2:$B$27) -> 1.0939504 | D13: 93.685272 | E13: =D13/ _xlfn.XLOOKUP(2025,$A$2:$A$27,$D$2:$D$27) -> 1.0921428 | F13: 3570.2549
... A27: 2050 | B27: 9.1152992 | C27: =B27/ _xlfn.XLOOKUP(2025,$A$2:$A$27,$B$2:$B$27) -> 1.3611787 | D27: 105.05097 | E27: =D27/ _xlfn.XLOOKUP(2025,$A$2:$A$27,$D$2:$D$27) -> 1.2246392 | F27: 4013.6313
A29: EIA 2025–2035 efficiency CAGR | B29: =(_xlfn.XLOOKUP(2035,$A$2:$A$27,$D$2:$D$27)/ _xlfn.XLOOKUP(2025,$A$2:$A$27,$D$2:$D$27))^(1/10)-1 -> 0.008030109

Sheet EPA_SAF
A1: RIN Year | B1: Month | C1: Producer Type | D1: Fuel (D Code) | E1: Fuel Category | F1: RINs | G1: Volume (Gal.) | H1: SAF_Flag | I1: Period
A2: 2018 | B2: 1 | C2: Domestic | D2: D3 | E2: Cellulosic Ethanol (EV 1.0) | F2: 760163 | G2: 760163 | H2: =--ISNUMBER(SEARCH("Jet Fuel",E2)) -> 0 | I2: =DATE(A2,B2,1) -> 43101
A3: 2018 | B3: 1 | C3: Domestic | D3: D3 | E3: Renewable Liquefied Natural Gas | F3: 186414 | G3: 186414 | H3: =--ISNUMBER(SEARCH("Jet Fuel",E3)) -> 0 | I3: =DATE(A3,B3,1) -> 43101
A4: 2018 | B4: 1 | C4: Domestic | D4: D3 | E4: Renewable Compressed Natural Gas | F4: 20688 | G4: 20688 | H4: =--ISNUMBER(SEARCH("Jet Fuel",E4)) -> 0 | I4: =DATE(A4,B4,1) -> 43101
A5: 2018 | B5: 1 | C5: Domestic | D5: D4 | E5: Biodiesel (EV 1.5) | F5: 165745904 | G5: 110496056 | H5: =--ISNUMBER(SEARCH("Jet Fuel",E5)) -> 0 | I5: =DATE(A5,B5,1) -> 43101
A6: 2018 | B6: 1 | C6: Foreign Generation | D6: D4 | E6: Non-ester Renewable Diesel (EV 1.7) | F6: 26685400 | G6: 15697294 | H6: =--ISNUMBER(SEARCH("Jet Fuel",E6)) -> 0 | I6: =DATE(A6,B6,1) -> 43101
A7: 2018 | B7: 1 | C7: Domestic | D7: D4 | E7: Non-ester Renewable Diesel (EV 1.7) | F7: 22710110 | G7: 13358879 | H7: =--ISNUMBER(SEARCH("Jet Fuel",E7)) -> 0 | I7: =DATE(A7,B7,1) -> 43101
A8: 2018 | B8: 1 | C8: Importer | D8: D4 | E8: Biodiesel (EV 1.5) | F8: 16044167 | G8: 10696089 | H8: =--ISNUMBER(SEARCH("Jet Fuel",E8)) -> 0 | I8: =DATE(A8,B8,1) -> 43101
A9: 2018 | B9: 1 | C9: Domestic | D9: D4 | E9: Renewable Jet Fuel (EV 1.6) | F9: 223543 | G9: 139714 | H9: =--ISNUMBER(SEARCH("Jet Fuel",E9)) -> 1 | I9: =DATE(A9,B9,1) -> 43101
A10: 2018 | B10: 1 | C10: Domestic | D10: D5 | E10: Renewable Naphtha (EV 1.5) | F10: 2631674 | G10: 1754449 | H10: =--ISNUMBER(SEARCH("Jet Fuel",E10)) -> 0 | I10: =DATE(A10,B10,1) -> 43101
A11: 2018 | B11: 1 | C11: Domestic | D11: D5 | E11: Non-cellulosic Ethanol (EV 1.0) | F11: 2191637 | G11: 2191637 | H11: =--ISNUMBER(SEARCH("Jet Fuel",E11)) -> 0 | I11: =DATE(A11,B11,1) -> 43101
A12: 2018 | B12: 1 | C12: Domestic | D12: D5 | E12: Non-ester Renewable Diesel (EV 1.7) | F12: 547014 | G12: 321773 | H12: =--ISNUMBER(SEARCH("Jet Fuel",E12)) -> 0 | I12: =DATE(A12,B12,1) -> 43101
A13: 2018 | B13: 1 | C13: Domestic | D13: D5 | E13: Renewable Heating Oil (EV 1.6) | F13: 422563 | G13: 264103 | H13: =--ISNUMBER(SEARCH("Jet Fuel",E13)) -> 0 | I13: =DATE(A13,B13,1) -> 43101
... A2160: 2026 | B2160: 7 | C2160: Importer | D2160: D6 | E2160: Non-cellulosic Ethanol (EV 1.0) | F2160: 1514114 | G2160: 1514114 | H2160: =--ISNUMBER(SEARCH("Jet Fuel",E2160)) -> 0 | I2160: =DATE(A2160,B2160,1) -> 46204

Sheet EPA_SAF_PIV
A1: SAF_Flag | H1: SAF_Flag
H2: Month
B3: Domestic | C3: Foreign Generation | D3: Importer | E3: Grand Total
A4: Row Labels | E4: Grand Total | I4: Domestic | J4: Foreign Generation | K4: Importer | L4: Grand Total
A5: 2018 | B5: 17441884577 | C5: 309846637 | D5: 305428514 | E5: 18057159728 | H5: Row Labels | L5: Grand Total
A6: 2019 | B6: 17354299933 | C6: 420373097 | D6: 434991489 | E6: 18209664519 | I6: 158951615015 | J6: 3050392200 | K6: 3305813393 | L6: 165307820608
A7: 2020 | B7: 15730996387 | C7: 435479892 | D7: 441621445 | E7: 16608097724 | I7: 158951615015 | J7: 3050392200 | K7: 3305813393 | L7: 165307820608
A8: 2021 | B8: 17255750754 | C8: 468147127 | D8: 320621854 | E8: 18044519735 | I8: 158951615015 | J8: 3050392200 | K8: 3305813393 | L8: 165307820608
A9: 2022 | B9: 18225123162 | C9: 454349188 | D9: 372340413 | E9: 19051812763 | H9: 43101 | I9: 1384988329 | J9: 31803799 | K9: 11758628 | L9: 1428550756
A10: 2023 | B10: 19634207642 | C10: 493035918 | D10: 590744405 | E10: 20717987965 | H10: 43132 | I10: 1257524467 | J10: 28296030 | K10: 15457621 | L10: 1301278118
A11: 2024 | B11: 20790006780 | C11: 387132522 | D11: 584843349 | E11: 21761982651 | H11: 43160 | I11: 1412228233 | J11: 28445622 | K11: 21540265 | L11: 1462214120
A12: 2025 | B12: 20272607349 | C12: 63656006 | D12: 180742650 | E12: 20517006005 | H12: 43191 | I12: 1413724796 | J12: 31753453 | K12: 19960865 | L12: 1465439114
A13: 2026 | B13: 12246738431 | C13: 18371813 | D13: 74479274 | E13: 12339589518 | H13: 43221 | I13: 1495406988 | J13: 31714034 | K13: 20536351 | L13: 1547657373
A14: Grand Total | B14: 158951615015 | C14: 3050392200 | D14: 3305813393 | E14: 165307820608 | H14: 43252 | I14: 1445468145 | J14: 28811262 | K14: 16659028 | L14: 1490938435
H15: 43282 | I15: 1554106812 | J15: 29674375 | K15: 9461417 | L15: 1593242604
H16: 43313 | I16: 1568635112 | J16: 29795498 | K16: 37566921 | L16: 1635997531
H17: 43344 | I17: 1426147420 | J17: 22397593 | K17: 20031105 | L17: 1468576118
H18: 43374 | I18: 1509655932 | J18: 0 | K18: 44305644 | L18: 1553961576
H19: 43405 | I19: 1452005038 | J19: 11371102 | K19: 28200556 | L19: 1491576696
H20: 43435 | I20: 1521993305 | J20: 35783869 | K20: 59950113 | L20: 1617727287
H21: 43466 | I21: 1339300927 | J21: 27498052 | K21: 13000599 | L21: 1379799578
H22: 43497 | I22: 1323635451 | J22: 33386661 | K22: 15164025 | L22: 1372186137
H23: 43525 | I23: 1398203645 | J23: 32948386 | K23: 26904896 | L23: 1458056927
H24: 43556 | I24: 1471829620 | J24: 35712304 | K24: 39118408 | L24: 1546660332
H25: 43586 | I25: 1514860264 | J25: 36623654 | K25: 19814613 | L25: 1571298531
H26: 43617 | I26: 1455128720 | J26: 35745741 | K26: 48361330 | L26: 1539235791
... H112: Grand Total | I112: 158951615015 | J112: 3050392200 | K112: 3305813393 | L112: 165307820608

Sheet Inputs
A1: Alaska Air Group Decarbonization Model — Inputs
A3: USER CONTROLS | B3: Value | C3: Units | D3: Model role | E3: Source / note
A4: Business activity adjustment vs FAA | B4: 0 | C4: % / year | D4: Adjusts FAA system ASM baseline; drives physical operating scale | E4: 0% = FAA baseline
A5: Operational efficiency adjustment vs EIA | B5: 0 | C5: % / year | D5: Adjusts EIA aircraft-efficiency baseline; drives fuel burn per unit activity | E5: 0% = EIA baseline
A6: SAF share in 2030 | B6: 0.1 | C6: % of liquid jet fuel | D6: 2030 SAF target endpoint | E6: Scenario input
A7: SAF share in 2040 | B7: 0.6 | C7: % of liquid jet fuel | D7: 2040 SAF target endpoint | E7: Scenario input; capped at 100%
A8: SAF lifecycle GHG reduction | B8: 0.8 | C8: % vs conventional | D8: Reduces lifecycle GHG intensity of SAF gallons | E8: Alaska states SAF can reduce lifecycle emissions by up to ~80%
A9: SAF market premium vs conventional | B9: 1 | C9: % premium | D9: Market SAF price before third-party support | E9: Scenario input; no universal transparent SAF spot price
A10: Corporate / partner share of SAF premium | B10: 0 | C10: % of SAF premium | D10: Reduces Alaska's net SAF premium; does not change physical SAF use | E10: Represents Scope 3 / book-and-claim / offtake support
A11: Fleet renewal share by 2040 | B11: 0 | C11: % of 2025 fleet-equivalent | D11: Incremental fleet benefit beyond EIA baseline | E11: Scenario input; 0% avoids double counting
A12: Ground equipment electrification by 2040 | B12: 0 | C12: % of vehicle emissions | D12: Reduces Scope 1 vehicle emissions | E12: Scenario input
A13: Novel propulsion share by 2040 | B13: 0 | C13: % of aircraft activity | D13: Displaces liquid-fuel aircraft activity with zero-carbon propulsion proxy | E13: Scenario input
A14: Carbon planning price | B14: 200 | C14: $ / tCO2e | D14: Single price applied to modeled residual emissions for 2040 closure cost | E14: Deliberately simple planning rate; carbon-market detail retained in assumptions/context
A15: Catalytic Capital | B15: 0 | C15: % of projected revenue | D15: Strategic investment that increases future SAF capacity after a lag | E15: Revenue-based control for usability; supply effect only
A16: SAF supply case | B16: Base | C16: Base / Conservative | D16: Selects published 2035 SAF production case | E16: Base = Rystad 190k bpd; Conservative = 110k bpd
A17: Post-2035 SAF supply growth | B17: 0.1 | C17: % / year | D17: Explicit growth after last published 2035 production anchor | E17: 0% default avoids hidden extrapolation
A20: BACKEND ASSUMPTIONS / PUBLISHED ANCHORS | B20: Value | C20: Units | D20: Use | E20: Source / note
A21: Fuel-burn advantage of renewed fleet | B21: 0.2 | C21: % vs replaced aircraft | D21: Multiplied by fleet-renewal share | E21: Alaska cites newer aircraft as ~15%–25% more efficient per seat; midpoint proxy
A22: Residual emissions neutralized in 2040 | B22: 1 | C22: % | D22: Share of modeled residual neutralized | E22: Net-zero closure assumption
A23: Model base year | B23: 2025 | C23: year | D23: Scenario start | E23: 2025 Alaska reporting year
A24: 2030 target year | B24: 2030 | C24: year | D24: Near-term target | E24: Alaska 2030 intensity goal
A25: 2040 net-zero year | B25: 2040 | C25: year | D25: Long-term target | E25: Alaska net-zero ambition
A26: SAF capacity capital-intensity proxy | B26: 14.666667 | C26: $ invested / annual gallon capacity | D26: Converts matured catalytic capital into incremental annual SAF capacity | E26: DOE: >$44B investment associated with >3B gal/yr announced 2030 capacity
A27: Catalytic capital deployment lag | B27: 3 | C27: years | D27: Delay before investment adds modeled capacity | E27: Stylized model assumption
A28: U.S. SAF probable production — 2030 | B28: 2048980612 | C28: gallons / year | D28: Base 2030 production anchor | E28: Peer-reviewed probable-production estimate
A29: U.S. SAF announced capacity — 2030 | B29: 3000000000 | C29: gallons / year | D29: Upper reference only | E29: DOE announced project capacity; not treated as realized production
A30: U.S. SAF production — 2035 base | B30: 2912700000 | C30: gallons / year | D30: Base 2035 production anchor | E30: Rystad base case: 190,000 bpd × 42 × 365
A31: U.S. SAF production — 2035 conservative | B31: 1686300000 | C31: gallons / year | D31: Conservative 2035 production anchor | E31: Rystad low case: 110,000 bpd × 42 × 365
A32: CORSIA reference price midpoint | B32: 59 | C32: $ / tCO2e | D32: Carbon-market context only | E32: MSCI 2033–35 range $27–$91/t midpoint
A33: Durable removal planning benchmark | B33: 200 | C33: $ / tCO2e | D33: Carbon-market context only | E33: Rounded planning rate near high-integrity removal market estimates; active model uses user Carbon planning price
A36: FAA forecast | B36: https://www.faa.gov/data_research/aviation/aerospace_forecasts/FY_2026-2046_Full_Forecast_Document_Tables.pdf
A37: EIA AEO | B37: https://www.eia.gov/outlooks/aeo/
A38: DOE SAF Liftoff | B38: https://www.energy.gov/articles/us-department-energy-releases-new-report-pathways-commercial-liftoff-sustainable-aviation
A39: 2030 SAF probable production | B39: https://www.sciencedirect.com/science/article/pii/S0961953425009274
A40: 2035 SAF cases | B40: https://www.rystadenergy.com/news/booming-biofuels-us-diesel-sustainable-aviation-fuel
A41: MSCI CORSIA | B41: https://www.msci.com/research-and-insights/paper/corsia-costs-and-implications-for-the-airline-industry
A42: Nasdaq/Puro context | B42: https://www.nasdaq.com/products/european-markets/carbon-removal-platform

Sheet Model
A1: Year | B1: Years From Base | C1: Business Activity Index | D1: Operational Efficiency Index | E1: Fleet Renewal Share | F1: Fleet Fuel Factor | G1: Novel Propulsion Share | H1: Pre-Propulsion Fuel Gallons | I1: Liquid Jet Fuel Gallons | J1: Target SAF Share | K1: Target SAF Gallons | L1: U.S. SAF Availability | M1: Market Capture Required | N1: SAF Supply Gap | O1: Effective SAF Share | P1: Effective SAF Gallons | Q1: Conventional Gallons | R1: Conventional Fuel $/gal | S1: SAF Market $/gal | T1: Alaska Net SAF $/gal | U1: Fuel Cost – No SAF | V1: Fuel Cost – With SAF | W1: Net Incremental SAF Cost | X1: Corporate / Partner Contribution | Y1: Projected Revenue | Z1: SAF Cost / Revenue | AA1: Carbon Mix Factor | AB1: Aircraft GHG Intensity (MtCO2e / 1,000 RTM) | AC1: Reduction vs 2019 | AD1: 2030 Target Low | AE1: 2030 Target High | AF1: 2040 Net Zero | AG1: Aircraft Emissions (tCO2e) | AH1: Ground Electrification Share | AI1: Vehicle Emissions (tCO2e) | AJ1: Facility Heating Emissions (tCO2e) | AK1: Scope 2 Market Emissions (tCO2e) | AL1: Operational Residual Emissions (tCO2e) | AM1: Carbon Planning Price | AN1: Carbon Closure Cost | AO1: Total Modeled Decarb Premium | AP1: Decarb Cost / Revenue
A2: 2025 | B2: =A2-Inputs!$B$23 -> 0 | C2: =INDEX('FAA Forecast'!$C$4:$C$19,MATCH(A2,'FAA Forecast'!$A$4:$A$19,0))*(1+Inputs!$B$4)^B2 -> 1 | D2: =INDEX(EIA_AEO!$E$2:$E$27,MATCH(A2,EIA_AEO!$A$2:$A$27,0))*(1+Inputs!$B$5)^B2 -> 1 | E2: =MIN(1,MAX(0,Inputs!$B$11*B2/(Inputs!$B$25-Inputs!$B$23))) -> 0 | F2: =1-E2*Inputs!$B$21 -> 1 | G2: =MIN(1,MAX(0,Inputs!$B$13*B2/(Inputs!$B$25-Inputs!$B$23))) -> 0 | H2: ='Alaska Base'!$C$6*C2/D2*F2 -> 1146000000 | I2: {=H2*(1-G2)} -> 1146000000 | J2: =MIN(1,MAX(0,IF(A2<=Inputs!$B$24,'Alaska Base'!$C$19+(Inputs!$B$6-'Alaska Base'!$C$19)*((A2-Inputs!$B$23)/(Inputs!$B$24-Inputs!$B$23)),Inputs!$B$6+(Inputs!$B$7-Inputs!$B$6)*((A2-Inputs!$B$24)/(Inputs!$B$25-Inputs!$B$24))))) -> 0.0095036161 | K2: =I2*J2 -> 10891144 | L2: =INDEX('SAF Supply'!$L$4:$L$26,MATCH(A2,'SAF Supply'!$A$4:$A$26,0)) -> 287728509 | M2: =IF(L2=0,NA(),K2/L2) -> 0.037852155 | N2: =MAX(0,K2-L2) -> 0 | O2: =IF(I2=0,0,MIN(J2,L2/I2)) -> 0.0095036161 | P2: =I2*O2 -> 10891144 | Q2: =I2-P2 -> 1135108856 | R2: ='Alaska Base'!$C$7*INDEX(EIA_AEO!$C$2:$C$27,MATCH(A2,EIA_AEO!$A$2:$A$27,0)) -> 2.51 | S2: =R2*(1+Inputs!$B$9) -> 5.02 | T2: =R2*(1+Inputs!$B$9*(1-Inputs!$B$10)) -> 5.02 | U2: =I2*R2 -> 2.87646e+09 | V2: =Q2*R2+P2*T2 -> 2.9037968e+09 | W2: =V2-U2 -> 27336771 | X2: =P2*R2*Inputs!$B$9*Inputs!$B$10 -> 0 | Y2: ='Alaska Base'!$C$8*C2 -> 14239000000 | Z2: =W2/Y2 -> 0.0019198519 | AA2: =1-O2*Inputs!$B$8 -> 0.99239711 | AB2: ='Alaska Base'!$C$3/D2*F2*(AA2/(1-'Alaska Base'!$C$19*Inputs!$B$8))*(1-G2) -> 1.33 | AC2: =1-AB2/'Alaska Base'!$C$2 -> 0.043165468 | AG2: =AB2*'Alaska Base'!$C$18*C2/1000 -> 10428326 | AH2: =MIN(1,MAX(0,Inputs!$B$12*B2/(Inputs!$B$25-Inputs!$B$23))) -> 0 | AI2: ='Alaska Base'!$C$13*C2*(1-AH2) -> 13789 | AJ2: ='Alaska Base'!$C$14*C2 -> 6385 | AK2: ='Alaska Base'!$C$16*C2 -> 13321 | AL2: =AG2+AI2+AJ2+AK2 -> 10461821 | AM2: =Inputs!$B$14 -> 200 | AN2: =IF(A2=Inputs!$B$25,AL2*AM2*Inputs!$B$22,0) -> 0 | AO2: =W2+AN2 -> 27336771 | AP2: =AO2/Y2 -> 0.0019198519
A3: 2026 | B3: 1 | C3: =INDEX('FAA Forecast'!$C$4:$C$19,MATCH(A3,'FAA Forecast'!$A$4:$A$19,0))*(1+Inputs!$B$4)^B3 -> 1.0220364 | D3: =INDEX(EIA_AEO!$E$2:$E$27,MATCH(A3,EIA_AEO!$A$2:$A$27,0))*(1+Inputs!$B$5)^B3 -> 1.0078635 | E3: =MIN(1,MAX(0,Inputs!$B$11*B3/(Inputs!$B$25-Inputs!$B$23))) -> 0 | F3: =1-E3*Inputs!$B$21 -> 1 | G3: 0 | H3: 1.1621154e+09 | I3: {=H3*(1-G3)} -> 1.1621154e+09 | J3: =MIN(1,MAX(0,IF(A3<=Inputs!$B$24,'Alaska Base'!$C$19+(Inputs!$B$6-'Alaska Base'!$C$19)*((A3-Inputs!$B$23)/(Inputs!$B$24-Inputs!$B$23)),Inputs!$B$6+(Inputs!$B$7-Inputs!$B$6)*((A3-Inputs!$B$24)/(Inputs!$B$25-Inputs!$B$24))))) -> 0.027602893 | K3: =I3*J3 -> 32077747 | L3: 4.2608269e+08 | M3: =IF(L3=0,NA(),K3/L3) -> 0.075285263 | N3: =MAX(0,K3-L3) -> 0 | O3: =IF(I3=0,0,MIN(J3,L3/I3)) -> 0.027602893 | P3: =I3*O3 -> 32077747 | Q3: =I3-P3 -> 1.1300377e+09 | R3: ='Alaska Base'!$C$7*INDEX(EIA_AEO!$C$2:$C$27,MATCH(A3,EIA_AEO!$A$2:$A$27,0)) -> 2.2385275 | S3: =R3*(1+Inputs!$B$9) -> 4.4770551 | T3: =R3*(1+Inputs!$B$9*(1-Inputs!$B$10)) -> 4.4770551 | U3: =I3*R3 -> 2.6014273e+09 | V3: =Q3*R3+P3*T3 -> 2.6732343e+09 | W3: =V3-U3 -> 71806920 | X3: =P3*R3*Inputs!$B$9*Inputs!$B$10 -> 0 | Y3: ='Alaska Base'!$C$8*C3 -> 1.4552776e+10 | Z3: =W3/Y3 -> 0.0049342422 | AA3: =1-O3*Inputs!$B$8 -> 0.97791769 | AB3: ='Alaska Base'!$C$3/D3*F3*(AA3/(1-'Alaska Base'!$C$19*Inputs!$B$8))*(1-G3) -> 1.3003694 | AC3: =1-AB3/'Alaska Base'!$C$2 -> 0.064482434 | AG3: =AB3*'Alaska Base'!$C$18*C3/1000 -> 10420680 | AH3: =MIN(1,MAX(0,Inputs!$B$12*B3/(Inputs!$B$25-Inputs!$B$23))) -> 0 | AI3: ='Alaska Base'!$C$13*C3*(1-AH3) -> 14092.859 | AJ3: ='Alaska Base'!$C$14*C3 -> 6525.7022 | AK3: ='Alaska Base'!$C$16*C3 -> 13614.546 | AL3: =AG3+AI3+AJ3+AK3 -> 10454913 | AM3: =Inputs!$B$14 -> 200 | AN3: =IF(A3=Inputs!$B$25,AL3*AM3*Inputs!$B$22,0) -> 0 | AO3: =W3+AN3 -> 71806920 | AP3: =AO3/Y3 -> 0.0049342422
A4: 2027 | B4: 2 | C4: =INDEX('FAA Forecast'!$C$4:$C$19,MATCH(A4,'FAA Forecast'!$A$4:$A$19,0))*(1+Inputs!$B$4)^B4 -> 1.0464028 | D4: =INDEX(EIA_AEO!$E$2:$E$27,MATCH(A4,EIA_AEO!$A$2:$A$27,0))*(1+Inputs!$B$5)^B4 -> 1.0158019 | E4: =MIN(1,MAX(0,Inputs!$B$11*B4/(Inputs!$B$25-Inputs!$B$23))) -> 0 | F4: =1-E4*Inputs!$B$21 -> 1 | G4: 0 | H4: 1.1805231e+09 | I4: {=H4*(1-G4)} -> 1.1805231e+09 | J4: =MIN(1,MAX(0,IF(A4<=Inputs!$B$24,'Alaska Base'!$C$19+(Inputs!$B$6-'Alaska Base'!$C$19)*((A4-Inputs!$B$23)/(Inputs!$B$24-Inputs!$B$23)),Inputs!$B$6+(Inputs!$B$7-Inputs!$B$6)*((A4-Inputs!$B$24)/(Inputs!$B$25-Inputs!$B$24))))) -> 0.04570217 | K4: =I4*J4 -> 53952468 | L4: 6.3096443e+08 | M4: =IF(L4=0,NA(),K4/L4) -> 0.08550794 | N4: =MAX(0,K4-L4) -> 0 | O4: =IF(I4=0,0,MIN(J4,L4/I4)) -> 0.04570217 | P4: =I4*O4 -> 53952468 | Q4: =I4-P4 -> 1.1265707e+09 | R4: ='Alaska Base'!$C$7*INDEX(EIA_AEO!$C$2:$C$27,MATCH(A4,EIA_AEO!$A$2:$A$27,0)) -> 2.4008773 | S4: =R4*(1+Inputs!$B$9) -> 4.8017547 | T4: =R4*(1+Inputs!$B$9*(1-Inputs!$B$10)) -> 4.8017547 | U4: =I4*R4 -> 2.8342912e+09 | V4: =Q4*R4+P4*T4 -> 2.9638245e+09 | W4: =V4-U4 -> 1.2953326e+08 | X4: =P4*R4*Inputs!$B$9*Inputs!$B$10 -> 0 | Y4: ='Alaska Base'!$C$8*C4 -> 1.489973e+10 | Z4: =W4/Y4 -> 0.0086936647 | AA4: =1-O4*Inputs!$B$8 -> 0.96343826 | AB4: ='Alaska Base'!$C$3/D4*F4*(AA4/(1-'Alaska Base'!$C$19*Inputs!$B$8))*(1-G4) -> 1.2711038 | AC4: =1-AB4/'Alaska Base'!$C$2 -> 0.085536842 | AG4: =AB4*'Alaska Base'!$C$18*C4/1000 -> 10429005 | AH4: =MIN(1,MAX(0,Inputs!$B$12*B4/(Inputs!$B$25-Inputs!$B$23))) -> 0 | AI4: ='Alaska Base'!$C$13*C4*(1-AH4) -> 14428.849 | AJ4: ='Alaska Base'!$C$14*C4 -> 6681.2822 | AK4: ='Alaska Base'!$C$16*C4 -> 13939.132 | AL4: =AG4+AI4+AJ4+AK4 -> 10464054 | AM4: =Inputs!$B$14 -> 200 | AN4: =IF(A4=Inputs!$B$25,AL4*AM4*Inputs!$B$22,0) -> 0 | AO4: =W4+AN4 -> 1.2953326e+08 | AP4: =AO4/Y4 -> 0.0086936647
A5: 2028 | B5: 3 | C5: =INDEX('FAA Forecast'!$C$4:$C$19,MATCH(A5,'FAA Forecast'!$A$4:$A$19,0))*(1+Inputs!$B$4)^B5 -> 1.0713503 | D5: =INDEX(EIA_AEO!$E$2:$E$27,MATCH(A5,EIA_AEO!$A$2:$A$27,0))*(1+Inputs!$B$5)^B5 -> 1.0239278 | E5: =MIN(1,MAX(0,Inputs!$B$11*B5/(Inputs!$B$25-Inputs!$B$23))) -> 0 | F5: =1-E5*Inputs!$B$21 -> 1 | G5: 0 | H5: 1.1990762e+09 | I5: {=H5*(1-G5)} -> 1.1990762e+09 | J5: =MIN(1,MAX(0,IF(A5<=Inputs!$B$24,'Alaska Base'!$C$19+(Inputs!$B$6-'Alaska Base'!$C$19)*((A5-Inputs!$B$23)/(Inputs!$B$24-Inputs!$B$23)),Inputs!$B$6+(Inputs!$B$7-Inputs!$B$6)*((A5-Inputs!$B$24)/(Inputs!$B$25-Inputs!$B$24))))) -> 0.063801446 | K5: =I5*J5 -> 76502795 | L5: 9.3436351e+08 | M5: =IF(L5=0,NA(),K5/L5) -> 0.081876908 | N5: =MAX(0,K5-L5) -> 0 | O5: =IF(I5=0,0,MIN(J5,L5/I5)) -> 0.063801446 | P5: =I5*O5 -> 76502795 | Q5: =I5-P5 -> 1.1225734e+09 | R5: ='Alaska Base'!$C$7*INDEX(EIA_AEO!$C$2:$C$27,MATCH(A5,EIA_AEO!$A$2:$A$27,0)) -> 2.469226 | S5: =R5*(1+Inputs!$B$9) -> 4.9384519 | T5: =R5*(1+Inputs!$B$9*(1-Inputs!$B$10)) -> 4.9384519 | U5: =I5*R5 -> 2.96079e+09 | V5: =Q5*R5+P5*T5 -> 3.1496927e+09 | W5: =V5-U5 -> 1.8890269e+08 | X5: =P5*R5*Inputs!$B$9*Inputs!$B$10 -> 0 | Y5: ='Alaska Base'!$C$8*C5 -> 1.5254956e+10 | Z5: =W5/Y5 -> 0.012383037 | AA5: =1-O5*Inputs!$B$8 -> 0.94895884 | AB5: ='Alaska Base'!$C$3/D5*F5*(AA5/(1-'Alaska Base'!$C$19*Inputs!$B$8))*(1-G5) -> 1.2420647 | AC5: =1-AB5/'Alaska Base'!$C$2 -> 0.10642829 | AG5: =AB5*'Alaska Base'!$C$18*C5/1000 -> 10433707 | AH5: =MIN(1,MAX(0,Inputs!$B$12*B5/(Inputs!$B$25-Inputs!$B$23))) -> 0 | AI5: ='Alaska Base'!$C$13*C5*(1-AH5) -> 14772.849 | AJ5: ='Alaska Base'!$C$14*C5 -> 6840.5714 | AK5: ='Alaska Base'!$C$16*C5 -> 14271.457 | AL5: =AG5+AI5+AJ5+AK5 -> 10469592 | AM5: =Inputs!$B$14 -> 200 | AN5: =IF(A5=Inputs!$B$25,AL5*AM5*Inputs!$B$22,0) -> 0 | AO5: =W5+AN5 -> 1.8890269e+08 | AP5: =AO5/Y5 -> 0.012383037
A6: 2029 | B6: 4 | C6: =INDEX('FAA Forecast'!$C$4:$C$19,MATCH(A6,'FAA Forecast'!$A$4:$A$19,0))*(1+Inputs!$B$4)^B6 -> 1.0968924 | D6: =INDEX(EIA_AEO!$E$2:$E$27,MATCH(A6,EIA_AEO!$A$2:$A$27,0))*(1+Inputs!$B$5)^B6 -> 1.0317824 | E6: =MIN(1,MAX(0,Inputs!$B$11*B6/(Inputs!$B$25-Inputs!$B$23))) -> 0 | F6: =1-E6*Inputs!$B$21 -> 1 | G6: 0 | H6: 1.2183176e+09 | I6: {=H6*(1-G6)} -> 1.2183176e+09 | J6: =MIN(1,MAX(0,IF(A6<=Inputs!$B$24,'Alaska Base'!$C$19+(Inputs!$B$6-'Alaska Base'!$C$19)*((A6-Inputs!$B$23)/(Inputs!$B$24-Inputs!$B$23)),Inputs!$B$6+(Inputs!$B$7-Inputs!$B$6)*((A6-Inputs!$B$24)/(Inputs!$B$25-Inputs!$B$24))))) -> 0.081900723 | K6: =I6*J6 -> 99781096 | L6: 1.3836519e+09 | M6: =IF(L6=0,NA(),K6/L6) -> 0.072114303 | N6: =MAX(0,K6-L6) -> 0 | O6: =IF(I6=0,0,MIN(J6,L6/I6)) -> 0.081900723 | P6: =I6*O6 -> 99781096 | Q6: =I6-P6 -> 1.1185365e+09 | R6: ='Alaska Base'!$C$7*INDEX(EIA_AEO!$C$2:$C$27,MATCH(A6,EIA_AEO!$A$2:$A$27,0)) -> 2.5288683 | S6: =R6*(1+Inputs!$B$9) -> 5.0577366 | T6: =R6*(1+Inputs!$B$9*(1-Inputs!$B$10)) -> 5.0577366 | U6: =I6*R6 -> 3.0809649e+09 | V6: =Q6*R6+P6*T6 -> 3.3332981e+09 | W6: =V6-U6 -> 2.5233325e+08 | X6: =P6*R6*Inputs!$B$9*Inputs!$B$10 -> 0 | Y6: ='Alaska Base'!$C$8*C6 -> 1.5618651e+10 | Z6: =W6/Y6 -> 0.016155892 | AA6: =1-O6*Inputs!$B$8 -> 0.93447942 | AB6: ='Alaska Base'!$C$3/D6*F6*(AA6/(1-'Alaska Base'!$C$19*Inputs!$B$8))*(1-G6) -> 1.2138018 | AC6: =1-AB6/'Alaska Base'!$C$2 -> 0.12676132 | AG6: =AB6*'Alaska Base'!$C$18*C6/1000 -> 10439381 | AH6: =MIN(1,MAX(0,Inputs!$B$12*B6/(Inputs!$B$25-Inputs!$B$23))) -> 0 | AI6: ='Alaska Base'!$C$13*C6*(1-AH6) -> 15125.05 | AJ6: ='Alaska Base'!$C$14*C6 -> 7003.6582 | AK6: ='Alaska Base'!$C$16*C6 -> 14611.704 | AL6: =AG6+AI6+AJ6+AK6 -> 10476122 | AM6: =Inputs!$B$14 -> 200 | AN6: =IF(A6=Inputs!$B$25,AL6*AM6*Inputs!$B$22,0) -> 0 | AO6: =W6+AN6 -> 2.5233325e+08 | AP6: =AO6/Y6 -> 0.016155892
A7: 2030 | B7: 5 | C7: =INDEX('FAA Forecast'!$C$4:$C$19,MATCH(A7,'FAA Forecast'!$A$4:$A$19,0))*(1+Inputs!$B$4)^B7 -> 1.1230436 | D7: =INDEX(EIA_AEO!$E$2:$E$27,MATCH(A7,EIA_AEO!$A$2:$A$27,0))*(1+Inputs!$B$5)^B7 -> 1.0397556 | E7: =MIN(1,MAX(0,Inputs!$B$11*B7/(Inputs!$B$25-Inputs!$B$23))) -> 0 | F7: =1-E7*Inputs!$B$21 -> 1 | G7: 0 | H7: 1.2377986e+09 | I7: {=H7*(1-G7)} -> 1.2377986e+09 | J7: =MIN(1,MAX(0,IF(A7<=Inputs!$B$24,'Alaska Base'!$C$19+(Inputs!$B$6-'Alaska Base'!$C$19)*((A7-Inputs!$B$23)/(Inputs!$B$24-Inputs!$B$23)),Inputs!$B$6+(Inputs!$B$7-Inputs!$B$6)*((A7-Inputs!$B$24)/(Inputs!$B$25-Inputs!$B$24))))) -> 0.1 | K7: =I7*J7 -> 1.2377986e+08 | L7: 2048980612 | M7: =IF(L7=0,NA(),K7/L7) -> 0.060410457 | N7: =MAX(0,K7-L7) -> 0 | O7: =IF(I7=0,0,MIN(J7,L7/I7)) -> 0.1 | P7: =I7*O7 -> 1.2377986e+08 | Q7: =I7-P7 -> 1.1140187e+09 | R7: ='Alaska Base'!$C$7*INDEX(EIA_AEO!$C$2:$C$27,MATCH(A7,EIA_AEO!$A$2:$A$27,0)) -> 2.5419344 | S7: =R7*(1+Inputs!$B$9) -> 5.0838689 | T7: =R7*(1+Inputs!$B$9*(1-Inputs!$B$10)) -> 5.0838689 | U7: =I7*R7 -> 3.1464028e+09 | V7: =Q7*R7+P7*T7 -> 3.461043e+09 | W7: =V7-U7 -> 3.1464028e+08 | X7: =P7*R7*Inputs!$B$9*Inputs!$B$10 -> 0 | Y7: ='Alaska Base'!$C$8*C7 -> 1.5991017e+10 | Z7: =W7/Y7 -> 0.019676064 | AA7: =1-O7*Inputs!$B$8 -> 0.92 | AB7: ='Alaska Base'!$C$3/D7*F7*(AA7/(1-'Alaska Base'!$C$19*Inputs!$B$8))*(1-G7) -> 1.1858308 | AC7: =1-AB7/'Alaska Base'!$C$2 -> 0.14688432 | AD7: ='Alaska Base'!$C$2*(1-10%) -> 1.251 | AE7: ='Alaska Base'!$C$2*(1-14%) -> 1.1954 | AG7: =AB7*'Alaska Base'!$C$18*C7/1000 -> 10441966 | AH7: =MIN(1,MAX(0,Inputs!$B$12*B7/(Inputs!$B$25-Inputs!$B$23))) -> 0 | AI7: ='Alaska Base'!$C$13*C7*(1-AH7) -> 15485.648 | AJ7: ='Alaska Base'!$C$14*C7 -> 7170.6332 | AK7: ='Alaska Base'!$C$16*C7 -> 14960.063 | AL7: =AG7+AI7+AJ7+AK7 -> 10479583 | AM7: =Inputs!$B$14 -> 200 | AN7: =IF(A7=Inputs!$B$25,AL7*AM7*Inputs!$B$22,0) -> 0 | AO7: =W7+AN7 -> 3.1464028e+08 | AP7: =AO7/Y7 -> 0.019676064
A8: 2031 | B8: 6 | C8: =INDEX('FAA Forecast'!$C$4:$C$19,MATCH(A8,'FAA Forecast'!$A$4:$A$19,0))*(1+Inputs!$B$4)^B8 -> 1.1498182 | D8: =INDEX(EIA_AEO!$E$2:$E$27,MATCH(A8,EIA_AEO!$A$2:$A$27,0))*(1+Inputs!$B$5)^B8 -> 1.047923 | E8: =MIN(1,MAX(0,Inputs!$B$11*B8/(Inputs!$B$25-Inputs!$B$23))) -> 0 | F8: =1-E8*Inputs!$B$21 -> 1 | G8: 0 | H8: 1.2574317e+09 | I8: {=H8*(1-G8)} -> 1.2574317e+09 | J8: =MIN(1,MAX(0,IF(A8<=Inputs!$B$24,'Alaska Base'!$C$19+(Inputs!$B$6-'Alaska Base'!$C$19)*((A8-Inputs!$B$23)/(Inputs!$B$24-Inputs!$B$23)),Inputs!$B$6+(Inputs!$B$7-Inputs!$B$6)*((A8-Inputs!$B$24)/(Inputs!$B$25-Inputs!$B$24))))) -> 0.15 | K8: =I8*J8 -> 1.8861475e+08 | L8: 2.1983125e+09 | M8: =IF(L8=0,NA(),K8/L8) -> 0.085799791 | N8: =MAX(0,K8-L8) -> 0 | O8: =IF(I8=0,0,MIN(J8,L8/I8)) -> 0.15 | P8: =I8*O8 -> 1.8861475e+08 | Q8: =I8-P8 -> 1.0688169e+09 | R8: ='Alaska Base'!$C$7*INDEX(EIA_AEO!$C$2:$C$27,MATCH(A8,EIA_AEO!$A$2:$A$27,0)) -> 2.5219273 | S8: =R8*(1+Inputs!$B$9) -> 5.0438546 | T8: =R8*(1+Inputs!$B$9*(1-Inputs!$B$10)) -> 5.0438546 | U8: =I8*R8 -> 3.1711513e+09 | V8: =Q8*R8+P8*T8 -> 3.646824e+09 | W8: =V8-U8 -> 4.756727e+08 | X8: =P8*R8*Inputs!$B$9*Inputs!$B$10 -> 0 | Y8: ='Alaska Base'!$C$8*C8 -> 1.6372261e+10 | Z8: =W8/Y8 -> 0.029053574 | AA8: =1-O8*Inputs!$B$8 -> 0.88 | AB8: ='Alaska Base'!$C$3/D8*F8*(AA8/(1-'Alaska Base'!$C$19*Inputs!$B$8))*(1-G8) -> 1.1254325 | AC8: =1-AB8/'Alaska Base'!$C$2 -> 0.19033636 | AG8: =AB8*'Alaska Base'!$C$18*C8/1000 -> 10146390 | AH8: =MIN(1,MAX(0,Inputs!$B$12*B8/(Inputs!$B$25-Inputs!$B$23))) -> 0 | AI8: ='Alaska Base'!$C$13*C8*(1-AH8) -> 15854.843 | AJ8: ='Alaska Base'!$C$14*C8 -> 7341.5891 | AK8: ='Alaska Base'!$C$16*C8 -> 15316.728 | AL8: =AG8+AI8+AJ8+AK8 -> 10184904 | AM8: =Inputs!$B$14 -> 200 | AN8: =IF(A8=Inputs!$B$25,AL8*AM8*Inputs!$B$22,0) -> 0 | AO8: =W8+AN8 -> 4.756727e+08 | AP8: =AO8/Y8 -> 0.029053574
A9: 2032 | B9: 7 | C9: =INDEX('FAA Forecast'!$C$4:$C$19,MATCH(A9,'FAA Forecast'!$A$4:$A$19,0))*(1+Inputs!$B$4)^B9 -> 1.1821971 | D9: =INDEX(EIA_AEO!$E$2:$E$27,MATCH(A9,EIA_AEO!$A$2:$A$27,0))*(1+Inputs!$B$5)^B9 -> 1.0566927 | E9: =MIN(1,MAX(0,Inputs!$B$11*B9/(Inputs!$B$25-Inputs!$B$23))) -> 0 | F9: =1-E9*Inputs!$B$21 -> 1 | G9: 0 | H9: 1.2821115e+09 | I9: {=H9*(1-G9)} -> 1.2821115e+09 | J9: =MIN(1,MAX(0,IF(A9<=Inputs!$B$24,'Alaska Base'!$C$19+(Inputs!$B$6-'Alaska Base'!$C$19)*((A9-Inputs!$B$23)/(Inputs!$B$24-Inputs!$B$23)),Inputs!$B$6+(Inputs!$B$7-Inputs!$B$6)*((A9-Inputs!$B$24)/(Inputs!$B$25-Inputs!$B$24))))) -> 0.2 | K9: =I9*J9 -> 2.5642229e+08 | L9: 2.3585279e+09 | M9: =IF(L9=0,NA(),K9/L9) -> 0.10872133 | N9: =MAX(0,K9-L9) -> 0 | O9: =IF(I9=0,0,MIN(J9,L9/I9)) -> 0.2 | P9: =I9*O9 -> 2.5642229e+08 | Q9: =I9-P9 -> 1.0256892e+09 | R9: ='Alaska Base'!$C$7*INDEX(EIA_AEO!$C$2:$C$27,MATCH(A9,EIA_AEO!$A$2:$A$27,0)) -> 2.5264374 | S9: =R9*(1+Inputs!$B$9) -> 5.0528749 | T9: =R9*(1+Inputs!$B$9*(1-Inputs!$B$10)) -> 5.0528749 | U9: =I9*R9 -> 3.2391744e+09 | V9: =Q9*R9+P9*T9 -> 3.8870093e+09 | W9: =V9-U9 -> 6.4783488e+08 | X9: =P9*R9*Inputs!$B$9*Inputs!$B$10 -> 0 | Y9: ='Alaska Base'!$C$8*C9 -> 1.6833304e+10 | Z9: =W9/Y9 -> 0.038485307 | AA9: =1-O9*Inputs!$B$8 -> 0.84 | AB9: ='Alaska Base'!$C$3/D9*F9*(AA9/(1-'Alaska Base'!$C$19*Inputs!$B$8))*(1-G9) -> 1.0653608 | AC9: =1-AB9/'Alaska Base'!$C$2 -> 0.23355336 | AG9: =AB9*'Alaska Base'!$C$18*C9/1000 -> 9875283.2 | AH9: =MIN(1,MAX(0,Inputs!$B$12*B9/(Inputs!$B$25-Inputs!$B$23))) -> 0 | AI9: ='Alaska Base'!$C$13*C9*(1-AH9) -> 16301.315 | AJ9: ='Alaska Base'!$C$14*C9 -> 7548.3283 | AK9: ='Alaska Base'!$C$16*C9 -> 15748.047 | AL9: =AG9+AI9+AJ9+AK9 -> 9914880.9 | AM9: =Inputs!$B$14 -> 200 | AN9: =IF(A9=Inputs!$B$25,AL9*AM9*Inputs!$B$22,0) -> 0 | AO9: =W9+AN9 -> 6.4783488e+08 | AP9: =AO9/Y9 -> 0.038485307
A10: 2033 | B10: 8 | C10: =INDEX('FAA Forecast'!$C$4:$C$19,MATCH(A10,'FAA Forecast'!$A$4:$A$19,0))*(1+Inputs!$B$4)^B10 -> 1.2154877 | D10: =INDEX(EIA_AEO!$E$2:$E$27,MATCH(A10,EIA_AEO!$A$2:$A$27,0))*(1+Inputs!$B$5)^B10 -> 1.0655601 | E10: =MIN(1,MAX(0,Inputs!$B$11*B10/(Inputs!$B$25-Inputs!$B$23))) -> 0 | F10: =1-E10*Inputs!$B$21 -> 1 | G10: 0 | H10: 1.3072458e+09 | I10: {=H10*(1-G10)} -> 1.3072458e+09 | J10: =MIN(1,MAX(0,IF(A10<=Inputs!$B$24,'Alaska Base'!$C$19+(Inputs!$B$6-'Alaska Base'!$C$19)*((A10-Inputs!$B$23)/(Inputs!$B$24-Inputs!$B$23)),Inputs!$B$6+(Inputs!$B$7-Inputs!$B$6)*((A10-Inputs!$B$24)/(Inputs!$B$25-Inputs!$B$24))))) -> 0.25 | K10: =I10*J10 -> 3.2681146e+08 | L10: 2.5304199e+09 | M10: =IF(L10=0,NA(),K10/L10) -> 0.12915306 | N10: =MAX(0,K10-L10) -> 0 | O10: =IF(I10=0,0,MIN(J10,L10/I10)) -> 0.25 | P10: =I10*O10 -> 3.2681146e+08 | Q10: =I10-P10 -> 9.8043439e+08 | R10: ='Alaska Base'!$C$7*INDEX(EIA_AEO!$C$2:$C$27,MATCH(A10,EIA_AEO!$A$2:$A$27,0)) -> 2.5946063 | S10: =R10*(1+Inputs!$B$9) -> 5.1892125 | T10: =R10*(1+Inputs!$B$9*(1-Inputs!$B$10)) -> 5.1892125 | U10: =I10*R10 -> 3.3917883e+09 | V10: =Q10*R10+P10*T10 -> 4.2397353e+09 | W10: =V10-U10 -> 8.4794707e+08 | X10: =P10*R10*Inputs!$B$9*Inputs!$B$10 -> 0 | Y10: ='Alaska Base'!$C$8*C10 -> 1.730733e+10 | Z10: =W10/Y10 -> 0.048993523 | AA10: =1-O10*Inputs!$B$8 -> 0.8 | AB10: ='Alaska Base'!$C$3/D10*F10*(AA10/(1-'Alaska Base'!$C$19*Inputs!$B$8))*(1-G10) -> 1.0061859 | AC10: =1-AB10/'Alaska Base'!$C$2 -> 0.27612529 | AG10: =AB10*'Alaska Base'!$C$18*C10/1000 -> 9589407 | AH10: =MIN(1,MAX(0,Inputs!$B$12*B10/(Inputs!$B$25-Inputs!$B$23))) -> 0 | AI10: ='Alaska Base'!$C$13*C10*(1-AH10) -> 16760.361 | AJ10: ='Alaska Base'!$C$14*C10 -> 7760.8893 | AK10: ='Alaska Base'!$C$16*C10 -> 16191.512 | AL10: =AG10+AI10+AJ10+AK10 -> 9630119.7 | AM10: =Inputs!$B$14 -> 200 | AN10: =IF(A10=Inputs!$B$25,AL10*AM10*Inputs!$B$22,0) -> 0 | AO10: =W10+AN10 -> 8.4794707e+08 | AP10: =AO10/Y10 -> 0.048993523
A11: 2034 | B11: 9 | C11: =INDEX('FAA Forecast'!$C$4:$C$19,MATCH(A11,'FAA Forecast'!$A$4:$A$19,0))*(1+Inputs!$B$4)^B11 -> 1.2497159 | D11: =INDEX(EIA_AEO!$E$2:$E$27,MATCH(A11,EIA_AEO!$A$2:$A$27,0))*(1+Inputs!$B$5)^B11 -> 1.0744024 | E11: =MIN(1,MAX(0,Inputs!$B$11*B11/(Inputs!$B$25-Inputs!$B$23))) -> 0 | F11: =1-E11*Inputs!$B$21 -> 1 | G11: 0 | H11: 1.3329963e+09 | I11: {=H11*(1-G11)} -> 1.3329963e+09 | J11: =MIN(1,MAX(0,IF(A11<=Inputs!$B$24,'Alaska Base'!$C$19+(Inputs!$B$6-'Alaska Base'!$C$19)*((A11-Inputs!$B$23)/(Inputs!$B$24-Inputs!$B$23)),Inputs!$B$6+(Inputs!$B$7-Inputs!$B$6)*((A11-Inputs!$B$24)/(Inputs!$B$25-Inputs!$B$24))))) -> 0.3 | K11: =I11*J11 -> 3.9989888e+08 | L11: 2.7148396e+09 | M11: =IF(L11=0,NA(),K11/L11) -> 0.14730111 | N11: =MAX(0,K11-L11) -> 0 | O11: =IF(I11=0,0,MIN(J11,L11/I11)) -> 0.3 | P11: =I11*O11 -> 3.9989888e+08 | Q11: =I11-P11 -> 9.330974e+08 | R11: ='Alaska Base'!$C$7*INDEX(EIA_AEO!$C$2:$C$27,MATCH(A11,EIA_AEO!$A$2:$A$27,0)) -> 2.6880359 | S11: =R11*(1+Inputs!$B$9) -> 5.3760718 | T11: =R11*(1+Inputs!$B$9*(1-Inputs!$B$10)) -> 5.3760718 | U11: =I11*R11 -> 3.5831418e+09 | V11: =Q11*R11+P11*T11 -> 4.6580844e+09 | W11: =V11-U11 -> 1.0749426e+09 | X11: =P11*R11*Inputs!$B$9*Inputs!$B$10 -> 0 | Y11: ='Alaska Base'!$C$8*C11 -> 1.7794705e+10 | Z11: =W11/Y11 -> 0.060408002 | AA11: =1-O11*Inputs!$B$8 -> 0.76 | AB11: ='Alaska Base'!$C$3/D11*F11*(AA11/(1-'Alaska Base'!$C$19*Inputs!$B$8))*(1-G11) -> 0.94800968 | AC11: =1-AB11/'Alaska Base'!$C$2 -> 0.31797865 | AG11: =AB11*'Alaska Base'!$C$18*C11/1000 -> 9289386.3 | AH11: =MIN(1,MAX(0,Inputs!$B$12*B11/(Inputs!$B$25-Inputs!$B$23))) -> 0 | AI11: ='Alaska Base'!$C$13*C11*(1-AH11) -> 17232.332 | AJ11: ='Alaska Base'!$C$14*C11 -> 7979.4359 | AK11: ='Alaska Base'!$C$16*C11 -> 16647.465 | AL11: =AG11+AI11+AJ11+AK11 -> 9331245.5 | AM11: =Inputs!$B$14 -> 200 | AN11: =IF(A11=Inputs!$B$25,AL11*AM11*Inputs!$B$22,0) -> 0 | AO11: =W11+AN11 -> 1.0749426e+09 | AP11: =AO11/Y11 -> 0.060408002
A12: 2035 | B12: 10 | C12: =INDEX('FAA Forecast'!$C$4:$C$19,MATCH(A12,'FAA Forecast'!$A$4:$A$19,0))*(1+Inputs!$B$4)^B12 -> 1.2849079 | D12: =INDEX(EIA_AEO!$E$2:$E$27,MATCH(A12,EIA_AEO!$A$2:$A$27,0))*(1+Inputs!$B$5)^B12 -> 1.0832658 | E12: =MIN(1,MAX(0,Inputs!$B$11*B12/(Inputs!$B$25-Inputs!$B$23))) -> 0 | F12: =1-E12*Inputs!$B$21 -> 1 | G12: 0 | H12: 1.3593196e+09 | I12: {=H12*(1-G12)} -> 1.3593196e+09 | J12: =MIN(1,MAX(0,IF(A12<=Inputs!$B$24,'Alaska Base'!$C$19+(Inputs!$B$6-'Alaska Base'!$C$19)*((A12-Inputs!$B$23)/(Inputs!$B$24-Inputs!$B$23)),Inputs!$B$6+(Inputs!$B$7-Inputs!$B$6)*((A12-Inputs!$B$24)/(Inputs!$B$25-Inputs!$B$24))))) -> 0.35 | K12: =I12*J12 -> 4.7576185e+08 | L12: 2912700000 | M12: =IF(L12=0,NA(),K12/L12) -> 0.16334049 | N12: =MAX(0,K12-L12) -> 0 | O12: =IF(I12=0,0,MIN(J12,L12/I12)) -> 0.35 | P12: =I12*O12 -> 4.7576185e+08 | Q12: =I12-P12 -> 8.8355773e+08 | R12: ='Alaska Base'!$C$7*INDEX(EIA_AEO!$C$2:$C$27,MATCH(A12,EIA_AEO!$A$2:$A$27,0)) -> 2.7183936 | S12: =R12*(1+Inputs!$B$9) -> 5.4367872 | T12: =R12*(1+Inputs!$B$9*(1-Inputs!$B$10)) -> 5.4367872 | U12: =I12*R12 -> 3.6951656e+09 | V12: =Q12*R12+P12*T12 -> 4.9884736e+09 | W12: =V12-U12 -> 1.293308e+09 | X12: =P12*R12*Inputs!$B$9*Inputs!$B$10 -> 0 | Y12: ='Alaska Base'!$C$8*C12 -> 1.8295804e+10 | Z12: =W12/Y12 -> 0.070688777 | AA12: =1-O12*Inputs!$B$8 -> 0.72 | AB12: ='Alaska Base'!$C$3/D12*F12*(AA12/(1-'Alaska Base'!$C$19*Inputs!$B$8))*(1-G12) -> 0.89076594 | AC12: =1-AB12/'Alaska Base'!$C$2 -> 0.35916119 | AG12: =AB12*'Alaska Base'!$C$18*C12/1000 -> 8974258.2 | AH12: =MIN(1,MAX(0,Inputs!$B$12*B12/(Inputs!$B$25-Inputs!$B$23))) -> 0 | AI12: ='Alaska Base'!$C$13*C12*(1-AH12) -> 17717.595 | AJ12: ='Alaska Base'!$C$14*C12 -> 8204.1369 | AK12: ='Alaska Base'!$C$16*C12 -> 17116.258 | AL12: =AG12+AI12+AJ12+AK12 -> 9017296.2 | AM12: =Inputs!$B$14 -> 200 | AN12: =IF(A12=Inputs!$B$25,AL12*AM12*Inputs!$B$22,0) -> 0 | AO12: =W12+AN12 -> 1.293308e+09 | AP12: =AO12/Y12 -> 0.070688777
A13: 2036 | B13: 11 | C13: =INDEX('FAA Forecast'!$C$4:$C$19,MATCH(A13,'FAA Forecast'!$A$4:$A$19,0))*(1+Inputs!$B$4)^B13 -> 1.3210909 | D13: =INDEX(EIA_AEO!$E$2:$E$27,MATCH(A13,EIA_AEO!$A$2:$A$27,0))*(1+Inputs!$B$5)^B13 -> 1.0921428 | E13: =MIN(1,MAX(0,Inputs!$B$11*B13/(Inputs!$B$25-Inputs!$B$23))) -> 0 | F13: =1-E13*Inputs!$B$21 -> 1 | G13: 0 | H13: 1.3862383e+09 | I13: {=H13*(1-G13)} -> 1.3862383e+09 | J13: =MIN(1,MAX(0,IF(A13<=Inputs!$B$24,'Alaska Base'!$C$19+(Inputs!$B$6-'Alaska Base'!$C$19)*((A13-Inputs!$B$23)/(Inputs!$B$24-Inputs!$B$23)),Inputs!$B$6+(Inputs!$B$7-Inputs!$B$6)*((A13-Inputs!$B$24)/(Inputs!$B$25-Inputs!$B$24))))) -> 0.4 | K13: =I13*J13 -> 5.5449534e+08 | L13: 2912700000 | M13: =IF(L13=0,NA(),K13/L13) -> 0.19037159 | N13: =MAX(0,K13-L13) -> 0 | O13: =IF(I13=0,0,MIN(J13,L13/I13)) -> 0.4 | P13: =I13*O13 -> 5.5449534e+08 | Q13: =I13-P13 -> 8.31743e+08 | R13: ='Alaska Base'!$C$7*INDEX(EIA_AEO!$C$2:$C$27,MATCH(A13,EIA_AEO!$A$2:$A$27,0)) -> 2.7458155 | S13: =R13*(1+Inputs!$B$9) -> 5.4916311 | T13: =R13*(1+Inputs!$B$9*(1-Inputs!$B$10)) -> 5.4916311 | U13: =I13*R13 -> 3.8063548e+09 | V13: =Q13*R13+P13*T13 -> 5.3288967e+09 | W13: =V13-U13 -> 1.5225419e+09 | X13: =P13*R13*Inputs!$B$9*Inputs!$B$10 -> 0 | Y13: ='Alaska Base'!$C$8*C13 -> 1.8811013e+10 | Z13: =W13/Y13 -> 0.080938856 | AA13: =1-O13*Inputs!$B$8 -> 0.68 | AB13: ='Alaska Base'!$C$3/D13*F13*(AA13/(1-'Alaska Base'!$C$19*Inputs!$B$8))*(1-G13) -> 0.83444103 | AC13: =1-AB13/'Alaska Base'!$C$2 -> 0.39968272 | AG13: =AB13*'Alaska Base'!$C$18*C13/1000 -> 8643533.3 | AH13: =MIN(1,MAX(0,Inputs!$B$12*B13/(Inputs!$B$25-Inputs!$B$23))) -> 0 | AI13: ='Alaska Base'!$C$13*C13*(1-AH13) -> 18216.523 | AJ13: ='Alaska Base'!$C$14*C13 -> 8435.1655 | AK13: ='Alaska Base'!$C$16*C13 -> 17598.252 | AL13: =AG13+AI13+AJ13+AK13 -> 8687783.3 | AM13: =Inputs!$B$14 -> 200 | AN13: =IF(A13=Inputs!$B$25,AL13*AM13*Inputs!$B$22,0) -> 0 | AO13: =W13+AN13 -> 1.5225419e+09 | AP13: =AO13/Y13 -> 0.080938856
A14: 2037 | B14: 12 | C14: =INDEX('FAA Forecast'!$C$4:$C$19,MATCH(A14,'FAA Forecast'!$A$4:$A$19,0))*(1+Inputs!$B$4)^B14 -> 1.3543812 | D14: =INDEX(EIA_AEO!$E$2:$E$27,MATCH(A14,EIA_AEO!$A$2:$A$27,0))*(1+Inputs!$B$5)^B14 -> 1.1009696 | E14: =MIN(1,MAX(0,Inputs!$B$11*B14/(Inputs!$B$25-Inputs!$B$23))) -> 0 | F14: =1-E14*Inputs!$B$21 -> 1 | G14: 0 | H14: 1.4097764e+09 | I14: {=H14*(1-G14)} -> 1.4097764e+09 | J14: =MIN(1,MAX(0,IF(A14<=Inputs!$B$24,'Alaska Base'!$C$19+(Inputs!$B$6-'Alaska Base'!$C$19)*((A14-Inputs!$B$23)/(Inputs!$B$24-Inputs!$B$23)),Inputs!$B$6+(Inputs!$B$7-Inputs!$B$6)*((A14-Inputs!$B$24)/(Inputs!$B$25-Inputs!$B$24))))) -> 0.45 | K14: =I14*J14 -> 6.3439938e+08 | L14: 2912700000 | M14: =IF(L14=0,NA(),K14/L14) -> 0.21780457 | N14: =MAX(0,K14-L14) -> 0 | O14: =IF(I14=0,0,MIN(J14,L14/I14)) -> 0.45 | P14: =I14*O14 -> 6.3439938e+08 | Q14: =I14-P14 -> 7.7537702e+08 | R14: ='Alaska Base'!$C$7*INDEX(EIA_AEO!$C$2:$C$27,MATCH(A14,EIA_AEO!$A$2:$A$27,0)) -> 2.8377208 | S14: =R14*(1+Inputs!$B$9) -> 5.6754416 | T14: =R14*(1+Inputs!$B$9*(1-Inputs!$B$10)) -> 5.6754416 | U14: =I14*R14 -> 4.0005518e+09 | V14: =Q14*R14+P14*T14 -> 5.8008001e+09 | W14: =V14-U14 -> 1.8002483e+09 | X14: =P14*R14*Inputs!$B$9*Inputs!$B$10 -> 0 | Y14: ='Alaska Base'!$C$8*C14 -> 1.9285034e+10 | Z14: =W14/Y14 -> 0.0933495 | AA14: =1-O14*Inputs!$B$8 -> 0.64 | AB14: ='Alaska Base'!$C$3/D14*F14*(AA14/(1-'Alaska Base'!$C$19*Inputs!$B$8))*(1-G14) -> 0.77905984 | AC14: =1-AB14/'Alaska Base'!$C$2 -> 0.4395253 | AG14: =AB14*'Alaska Base'!$C$18*C14/1000 -> 8273222.4 | AH14: =MIN(1,MAX(0,Inputs!$B$12*B14/(Inputs!$B$25-Inputs!$B$23))) -> 0 | AI14: ='Alaska Base'!$C$13*C14*(1-AH14) -> 18675.563 | AJ14: ='Alaska Base'!$C$14*C14 -> 8647.7242 | AK14: ='Alaska Base'!$C$16*C14 -> 18041.712 | AL14: =AG14+AI14+AJ14+AK14 -> 8318587.4 | AM14: =Inputs!$B$14 -> 200 | AN14: =IF(A14=Inputs!$B$25,AL14*AM14*Inputs!$B$22,0) -> 0 | AO14: =W14+AN14 -> 1.8002483e+09 | AP14: =AO14/Y14 -> 0.0933495
A15: 2038 | B15: 13 | C15: =INDEX('FAA Forecast'!$C$4:$C$19,MATCH(A15,'FAA Forecast'!$A$4:$A$19,0))*(1+Inputs!$B$4)^B15 -> 1.3885104 | D15: =INDEX(EIA_AEO!$E$2:$E$27,MATCH(A15,EIA_AEO!$A$2:$A$27,0))*(1+Inputs!$B$5)^B15 -> 1.1100108 | E15: =MIN(1,MAX(0,Inputs!$B$11*B15/(Inputs!$B$25-Inputs!$B$23))) -> 0 | F15: =1-E15*Inputs!$B$21 -> 1 | G15: 0 | H15: 1.4335293e+09 | I15: {=H15*(1-G15)} -> 1.4335293e+09 | J15: =MIN(1,MAX(0,IF(A15<=Inputs!$B$24,'Alaska Base'!$C$19+(Inputs!$B$6-'Alaska Base'!$C$19)*((A15-Inputs!$B$23)/(Inputs!$B$24-Inputs!$B$23)),Inputs!$B$6+(Inputs!$B$7-Inputs!$B$6)*((A15-Inputs!$B$24)/(Inputs!$B$25-Inputs!$B$24))))) -> 0.5 | K15: =I15*J15 -> 7.1676465e+08 | L15: 2912700000 | M15: =IF(L15=0,NA(),K15/L15) -> 0.24608255 | N15: =MAX(0,K15-L15) -> 0 | O15: =IF(I15=0,0,MIN(J15,L15/I15)) -> 0.5 | P15: =I15*O15 -> 7.1676465e+08 | Q15: =I15-P15 -> 7.1676465e+08 | R15: ='Alaska Base'!$C$7*INDEX(EIA_AEO!$C$2:$C$27,MATCH(A15,EIA_AEO!$A$2:$A$27,0)) -> 2.8738181 | S15: =R15*(1+Inputs!$B$9) -> 5.7476362 | T15: =R15*(1+Inputs!$B$9*(1-Inputs!$B$10)) -> 5.7476362 | U15: =I15*R15 -> 4.1197025e+09 | V15: =Q15*R15+P15*T15 -> 6.1795537e+09 | W15: =V15-U15 -> 2.0598512e+09 | X15: =P15*R15*Inputs!$B$9*Inputs!$B$10 -> 0 | Y15: ='Alaska Base'!$C$8*C15 -> 1.9771e+10 | Z15: =W15/Y15 -> 0.10418548 | AA15: =1-O15*Inputs!$B$8 -> 0.6 | AB15: ='Alaska Base'!$C$3/D15*F15*(AA15/(1-'Alaska Base'!$C$19*Inputs!$B$8))*(1-G15) -> 0.72441963 | AC15: =1-AB15/'Alaska Base'!$C$2 -> 0.4788348 | AG15: =AB15*'Alaska Base'!$C$18*C15/1000 -> 7886827 | AH15: =MIN(1,MAX(0,Inputs!$B$12*B15/(Inputs!$B$25-Inputs!$B$23))) -> 0 | AI15: ='Alaska Base'!$C$13*C15*(1-AH15) -> 19146.17 | AJ15: ='Alaska Base'!$C$14*C15 -> 8865.6392 | AK15: ='Alaska Base'!$C$16*C15 -> 18496.348 | AL15: =AG15+AI15+AJ15+AK15 -> 7933335.2 | AM15: =Inputs!$B$14 -> 200 | AN15: =IF(A15=Inputs!$B$25,AL15*AM15*Inputs!$B$22,0) -> 0 | AO15: =W15+AN15 -> 2.0598512e+09 | AP15: =AO15/Y15 -> 0.10418548
A16: 2039 | B16: 14 | C16: =INDEX('FAA Forecast'!$C$4:$C$19,MATCH(A16,'FAA Forecast'!$A$4:$A$19,0))*(1+Inputs!$B$4)^B16 -> 1.4234997 | D16: =INDEX(EIA_AEO!$E$2:$E$27,MATCH(A16,EIA_AEO!$A$2:$A$27,0))*(1+Inputs!$B$5)^B16 -> 1.1189377 | E16: =MIN(1,MAX(0,Inputs!$B$11*B16/(Inputs!$B$25-Inputs!$B$23))) -> 0 | F16: =1-E16*Inputs!$B$21 -> 1 | G16: 0 | H16: 1.457928e+09 | I16: {=H16*(1-G16)} -> 1.457928e+09 | J16: =MIN(1,MAX(0,IF(A16<=Inputs!$B$24,'Alaska Base'!$C$19+(Inputs!$B$6-'Alaska Base'!$C$19)*((A16-Inputs!$B$23)/(Inputs!$B$24-Inputs!$B$23)),Inputs!$B$6+(Inputs!$B$7-Inputs!$B$6)*((A16-Inputs!$B$24)/(Inputs!$B$25-Inputs!$B$24))))) -> 0.55 | K16: =I16*J16 -> 8.0186041e+08 | L16: 2912700000 | M16: =IF(L16=0,NA(),K16/L16) -> 0.27529797 | N16: =MAX(0,K16-L16) -> 0 | O16: =IF(I16=0,0,MIN(J16,L16/I16)) -> 0.55 | P16: =I16*O16 -> 8.0186041e+08 | Q16: =I16-P16 -> 6.5606761e+08 | R16: ='Alaska Base'!$C$7*INDEX(EIA_AEO!$C$2:$C$27,MATCH(A16,EIA_AEO!$A$2:$A$27,0)) -> 2.9388201 | S16: =R16*(1+Inputs!$B$9) -> 5.8776402 | T16: =R16*(1+Inputs!$B$9*(1-Inputs!$B$10)) -> 5.8776402 | U16: =I16*R16 -> 4.2845881e+09 | V16: =Q16*R16+P16*T16 -> 6.6411116e+09 | W16: =V16-U16 -> 2.3565235e+09 | X16: =P16*R16*Inputs!$B$9*Inputs!$B$10 -> 0 | Y16: ='Alaska Base'!$C$8*C16 -> 2.0269212e+10 | Z16: =W16/Y16 -> 0.11626123 | AA16: =1-O16*Inputs!$B$8 -> 0.56 | AB16: ='Alaska Base'!$C$3/D16*F16*(AA16/(1-'Alaska Base'!$C$19*Inputs!$B$8))*(1-G16) -> 0.67073083 | AC16: =1-AB16/'Alaska Base'!$C$2 -> 0.51745983 | AG16: =AB16*'Alaska Base'!$C$18*C16/1000 -> 7486323.7 | AH16: =MIN(1,MAX(0,Inputs!$B$12*B16/(Inputs!$B$25-Inputs!$B$23))) -> 0 | AI16: ='Alaska Base'!$C$13*C16*(1-AH16) -> 19628.637 | AJ16: ='Alaska Base'!$C$14*C16 -> 9089.0454 | AK16: ='Alaska Base'!$C$16*C16 -> 18962.439 | AL16: =AG16+AI16+AJ16+AK16 -> 7534003.8 | AM16: =Inputs!$B$14 -> 200 | AN16: =IF(A16=Inputs!$B$25,AL16*AM16*Inputs!$B$22,0) -> 0 | AO16: =W16+AN16 -> 2.3565235e+09 | AP16: =AO16/Y16 -> 0.11626123
A17: 2040 | B17: 15 | C17: =INDEX('FAA Forecast'!$C$4:$C$19,MATCH(A17,'FAA Forecast'!$A$4:$A$19,0))*(1+Inputs!$B$4)^B17 -> 1.4593706 | D17: =INDEX(EIA_AEO!$E$2:$E$27,MATCH(A17,EIA_AEO!$A$2:$A$27,0))*(1+Inputs!$B$5)^B17 -> 1.1280637 | E17: =MIN(1,MAX(0,Inputs!$B$11*B17/(Inputs!$B$25-Inputs!$B$23))) -> 0 | F17: =1-E17*Inputs!$B$21 -> 1 | G17: 0 | H17: 1.4825747e+09 | I17: {=H17*(1-G17)} -> 1.4825747e+09 | J17: =MIN(1,MAX(0,IF(A17<=Inputs!$B$24,'Alaska Base'!$C$19+(Inputs!$B$6-'Alaska Base'!$C$19)*((A17-Inputs!$B$23)/(Inputs!$B$24-Inputs!$B$23)),Inputs!$B$6+(Inputs!$B$7-Inputs!$B$6)*((A17-Inputs!$B$24)/(Inputs!$B$25-Inputs!$B$24))))) -> 0.6 | K17: =I17*J17 -> 8.8954484e+08 | L17: 2912700000 | M17: =IF(L17=0,NA(),K17/L17) -> 0.30540215 | N17: =MAX(0,K17-L17) -> 0 | O17: =IF(I17=0,0,MIN(J17,L17/I17)) -> 0.6 | P17: =I17*O17 -> 8.8954484e+08 | Q17: =I17-P17 -> 5.930299e+08 | R17: ='Alaska Base'!$C$7*INDEX(EIA_AEO!$C$2:$C$27,MATCH(A17,EIA_AEO!$A$2:$A$27,0)) -> 2.974625 | S17: =R17*(1+Inputs!$B$9) -> 5.94925 | T17: =R17*(1+Inputs!$B$9*(1-Inputs!$B$10)) -> 5.94925 | U17: =I17*R17 -> 4.4101039e+09 | V17: =Q17*R17+P17*T17 -> 7.0561662e+09 | W17: =V17-U17 -> 2.6460623e+09 | X17: =P17*R17*Inputs!$B$9*Inputs!$B$10 -> 0 | Y17: ='Alaska Base'!$C$8*C17 -> 2.0779978e+10 | Z17: =W17/Y17 -> 0.12733711 | AA17: =1-O17*Inputs!$B$8 -> 0.52 | AB17: ='Alaska Base'!$C$3/D17*F17*(AA17/(1-'Alaska Base'!$C$19*Inputs!$B$8))*(1-G17) -> 0.61778289 | AC17: =1-AB17/'Alaska Base'!$C$2 -> 0.55555187 | AF17: 0 | AG17: =AB17*'Alaska Base'!$C$18*C17/1000 -> 7069105 | AH17: =MIN(1,MAX(0,Inputs!$B$12*B17/(Inputs!$B$25-Inputs!$B$23))) -> 0 | AI17: ='Alaska Base'!$C$13*C17*(1-AH17) -> 20123.261 | AJ17: ='Alaska Base'!$C$14*C17 -> 9318.0813 | AK17: ='Alaska Base'!$C$16*C17 -> 19440.276 | AL17: =AG17+AI17+AJ17+AK17 -> 7117986.6 | AM17: =Inputs!$B$14 -> 200 | AN17: =IF(A17=Inputs!$B$25,AL17*AM17*Inputs!$B$22,0) -> 1.4235973e+09 | AO17: =W17+AN17 -> 4.0696597e+09 | AP17: =AO17/Y17 -> 0.19584523

Sheet Outputs
A1: Decision Outputs
A3: 2030 TARGET + SAF MARKET + REVENUE BURDEN | B3: Value | C3: Units | D3: Interpretation
A4: Business Activity Index | B4: =INDEX(Model!$C$2:$C$17,MATCH(Inputs!$B$24,Model!$A$2:$A$17,0)) -> 1.1230436 | C4: index | D4: FAA system ASM baseline plus user adjustment
A5: Operational Efficiency Index | B5: =INDEX(Model!$D$2:$D$17,MATCH(Inputs!$B$24,Model!$A$2:$A$17,0)) -> 1.0397556 | C5: index | D5: EIA aircraft-efficiency baseline plus user adjustment
A6: Fleet Fuel Factor | B6: =INDEX(Model!$F$2:$F$17,MATCH(Inputs!$B$24,Model!$A$2:$A$17,0)) -> 1 | C6: factor | D6: Incremental fleet-renewal effect; 1.00 = none
A7: Novel Propulsion Share | B7: =INDEX(Model!$G$2:$G$17,MATCH(Inputs!$B$24,Model!$A$2:$A$17,0)) -> 0 | C7: % | D7: Zero-carbon propulsion proxy
A8: Target SAF Share | B8: =INDEX(Model!$J$2:$J$17,MATCH(Inputs!$B$24,Model!$A$2:$A$17,0)) -> 0.1 | C8: % | D8: User-selected 2030 endpoint
A9: Effective SAF Share | B9: =INDEX(Model!$O$2:$O$17,MATCH(Inputs!$B$24,Model!$A$2:$A$17,0)) -> 0.1 | C9: % | D9: Target share after physical U.S. supply constraint
A10: Adjusted U.S. SAF Availability | B10: =INDEX(Model!$L$2:$L$17,MATCH(Inputs!$B$24,Model!$A$2:$A$17,0)) -> 2048980612 | C10: gallons / year | D10: Selected supply case + matured catalytic capacity
A11: Target SAF Gallons | B11: =INDEX(Model!$K$2:$K$17,MATCH(Inputs!$B$24,Model!$A$2:$A$17,0)) -> 1.2377986e+08 | C11: gallons | D11: Desired Alaska SAF procurement
A12: Effective SAF Gallons | B12: =INDEX(Model!$P$2:$P$17,MATCH(Inputs!$B$24,Model!$A$2:$A$17,0)) -> 1.2377986e+08 | C12: gallons | D12: Supply-constrained Alaska SAF procurement
A13: Market Capture Required | B13: =INDEX(Model!$M$2:$M$17,MATCH(Inputs!$B$24,Model!$A$2:$A$17,0)) -> 0.060410457 | C13: % of U.S. supply | D13: Share of adjusted U.S. supply Alaska must secure
A14: SAF Supply Gap | B14: =INDEX(Model!$N$2:$N$17,MATCH(Inputs!$B$24,Model!$A$2:$A$17,0)) -> 0 | C14: gallons | D14: Shortfall if target exceeds total modeled U.S. availability
A15: Required SAF Share — 10% Goal | B15: =IF(B7>=1,0,MIN(1,MAX(0,(1-(('Alaska Base'!$C$2*(1-10%))*B5/'Alaska Base'!$C$3/B6/(1-B7)*(1-'Alaska Base'!$C$19*Inputs!$B$8)))/Inputs!$B$8))) -> 0.036799937 | C15: % | D15: Minimum effective SAF share for 10% intensity reduction
A16: Required SAF Share — 14% Goal | B16: =IF(B7>=1,0,MIN(1,MAX(0,(1-(('Alaska Base'!$C$2*(1-14%))*B5/'Alaska Base'!$C$3/B6/(1-B7)*(1-'Alaska Base'!$C$19*Inputs!$B$8)))/Inputs!$B$8))) -> 0.090719939 | C16: % | D16: Minimum effective SAF share for 14% intensity reduction
A17: Required SAF Gallons — 10% Goal | B17: =B15*INDEX(Model!$I$2:$I$17,MATCH(Inputs!$B$24,Model!$A$2:$A$17,0)) -> 45550908 | C17: gallons | D17: Physical SAF requirement for lower target
A18: Required SAF Gallons — 14% Goal | B18: =B16*INDEX(Model!$I$2:$I$17,MATCH(Inputs!$B$24,Model!$A$2:$A$17,0)) -> 1.1229301e+08 | C18: gallons | D18: Physical SAF requirement for upper target
A19: Required Market Capture — 10% Goal | B19: =IF(B10=0,NA(),B17/B10) -> 0.02223101 | C19: % of U.S. supply | D19: Required gallons / adjusted supply
A20: Required Market Capture — 14% Goal | B20: =IF(B10=0,NA(),B18/B10) -> 0.05480433 | C20: % of U.S. supply | D20: Required gallons / adjusted supply
A21: Modeled GHG Intensity | B21: =INDEX(Model!$AB$2:$AB$17,MATCH(Inputs!$B$24,Model!$A$2:$A$17,0)) -> 1.1858308 | C21: MtCO2e / 1,000 RTM | D21: Supply-constrained emissions-intensity result
A22: Reduction vs 2019 | B22: =INDEX(Model!$AC$2:$AC$17,MATCH(Inputs!$B$24,Model!$A$2:$A$17,0)) -> 0.14688432 | C22: % | D22: Reduction from 2019 baseline
A23: Target Status | B23: =IF(B21<='Alaska Base'!$C$2*(1-14%),"Meets 14% target",IF(B21<='Alaska Base'!$C$2*(1-10%),"Within 10%–14% target range","Misses 2030 target")) -> Meets 14% target | D23: 2030 target attainment
A24: Projected Revenue | B24: =INDEX(Model!$Y$2:$Y$17,MATCH(Inputs!$B$24,Model!$A$2:$A$17,0)) -> 1.5991017e+10 | C24: $ | D24: 2025 revenue scaled with business activity
A25: Net Incremental SAF Cost | B25: =INDEX(Model!$W$2:$W$17,MATCH(Inputs!$B$24,Model!$A$2:$A$17,0)) -> 3.1464028e+08 | C25: $ | D25: SAF premium borne by Alaska after partner support
A26: Corporate / Partner Contribution | B26: =INDEX(Model!$X$2:$X$17,MATCH(Inputs!$B$24,Model!$A$2:$A$17,0)) -> 0 | C26: $ | D26: Premium shifted to third-party environmental-attribute buyers
A27: SAF Cost / Revenue | B27: =INDEX(Model!$Z$2:$Z$17,MATCH(Inputs!$B$24,Model!$A$2:$A$17,0)) -> 0.019676064 | C27: % revenue | D27: Net SAF premium / projected revenue
A28: Baseline Aircraft Capital / Revenue | B28: =INDEX('Capital Allocation'!$E$4:$E$9,MATCH(2030,'Capital Allocation'!$A$4:$A$9,0)) -> 0.065661863 | C28: % revenue | D28: Disclosed capital/commitment burden normalized to revenue
A29: Known Capital + SAF + Catalytic / Revenue | B29: =INDEX('Capital Allocation'!$J$4:$J$9,MATCH(2030,'Capital Allocation'!$A$4:$A$9,0)) -> 0.085337927 | C29: % revenue | D29: Indicative modeled spending burden; not a solvency ratio
A32: 2040 NET-ZERO + REVENUE BURDEN | B32: Value | C32: Units | D32: Interpretation
A33: Business Activity Index | B33: =INDEX(Model!$C$2:$C$17,MATCH(Inputs!$B$25,Model!$A$2:$A$17,0)) -> 1.4593706 | C33: index | D33: FAA system ASM baseline plus user adjustment
A34: Operational Efficiency Index | B34: =INDEX(Model!$D$2:$D$17,MATCH(Inputs!$B$25,Model!$A$2:$A$17,0)) -> 1.1280637 | C34: index | D34: EIA aircraft-efficiency baseline plus user adjustment
A35: Fleet Renewal Share | B35: =INDEX(Model!$E$2:$E$17,MATCH(Inputs!$B$25,Model!$A$2:$A$17,0)) -> 0 | C35: % | D35: User-controlled incremental renewal share
A36: Novel Propulsion Share | B36: =INDEX(Model!$G$2:$G$17,MATCH(Inputs!$B$25,Model!$A$2:$A$17,0)) -> 0 | C36: % | D36: Zero-carbon propulsion proxy
A37: Target SAF Share | B37: =INDEX(Model!$J$2:$J$17,MATCH(Inputs!$B$25,Model!$A$2:$A$17,0)) -> 0.6 | C37: % | D37: User-selected 2040 endpoint
A38: Effective SAF Share | B38: =INDEX(Model!$O$2:$O$17,MATCH(Inputs!$B$25,Model!$A$2:$A$17,0)) -> 0.6 | C38: % | D38: Supply-constrained SAF share
A39: Adjusted U.S. SAF Availability | B39: =INDEX(Model!$L$2:$L$17,MATCH(Inputs!$B$25,Model!$A$2:$A$17,0)) -> 2912700000 | C39: gallons / year | D39: Selected 2035 case + explicit post-2035 growth + catalytic capacity
A40: Market Capture Required | B40: =INDEX(Model!$M$2:$M$17,MATCH(Inputs!$B$25,Model!$A$2:$A$17,0)) -> 0.30540215 | C40: % of U.S. supply | D40: Share of adjusted U.S. supply Alaska must secure
A41: SAF Supply Gap | B41: =INDEX(Model!$N$2:$N$17,MATCH(Inputs!$B$25,Model!$A$2:$A$17,0)) -> 0 | C41: gallons | D41: Shortfall if target exceeds modeled U.S. availability
A42: Modeled Aircraft GHG Intensity | B42: =INDEX(Model!$AB$2:$AB$17,MATCH(Inputs!$B$25,Model!$A$2:$A$17,0)) -> 0.61778289 | C42: MtCO2e / 1,000 RTM | D42: Aircraft intensity after physical levers
A43: Reduction vs 2019 | B43: =INDEX(Model!$AC$2:$AC$17,MATCH(Inputs!$B$25,Model!$A$2:$A$17,0)) -> 0.55555187 | C43: % | D43: Aircraft intensity reduction
...

Sheet Dashboard
A1: Alaska Air Group Decarbonization Scenario Dashboard
P2: Year | Q2: GHG Intensity | R2: 2030 10% | S2: 2030 14% | T2: Net Zero | V2: Year | W2: Base SAF Supply | X2: Conservative SAF Supply | Y2: Adjusted Selected Supply | Z2: Alaska Target SAF | AB2: 2030 SAF Share | AC2: Percent | AE2: 2030 Revenue Burden | AF2: Percent
P3: =Model!A2 -> 2025 | Q3: =Model!AB2 -> 1.33 | R3: ='Alaska Base'!$C$2*(1-10%) -> 1.251 | S3: ='Alaska Base'!$C$2*(1-14%) -> 1.1954 | T3: 0 | V3: ='SAF Supply'!A11 -> 2025 | W3: ='SAF Supply'!D11 -> 287728509 | X3: ='SAF Supply'!E11 -> 287728509 | Y3: ='SAF Supply'!L11 -> 287728509 | Z3: ='SAF Supply'!M11 -> 10891144 | AB3: Required — 10% | AC3: =Outputs!B15*100 -> 3.6799937 | AE3: Baseline aircraft capital | AF3: =Outputs!B28*100 -> 6.5661863
A4: 2030 Goal Test | F4: SAF Market Feasibility | K4: Economics as Share of Revenue | P4: =Model!A3 -> 2026 | Q4: =Model!AB3 -> 1.3003694 | R4: ='Alaska Base'!$C$2*(1-10%) -> 1.251 | S4: ='Alaska Base'!$C$2*(1-14%) -> 1.1954 | T4: 0 | V4: ='SAF Supply'!A12 -> 2026 | W4: ='SAF Supply'!D12 -> 4.2608269e+08 | X4: ='SAF Supply'!E12 -> 3.4338245e+08 | Y4: ='SAF Supply'!L12 -> 4.2608269e+08 | Z4: ='SAF Supply'!M12 -> 32077747 | AB4: Required — 14% | AC4: =Outputs!B16*100 -> 9.0719939 | AE4: Net SAF premium | AF4: =Outputs!B27*100 -> 1.9676064
